### 环境

* 系统版本：Win10 专业版1903
* 设备：Surface Go
* Tensorflow版本：Tensorflow-gpu 1.14
* Python版本：Python3.6.8-Anaconda custom(64-bit)
* CUDA版本：None
* cuDNN版本：None
* GPU：None

### BUG描述

构建自定义keras层时，弹出警告

### 日志

```
WARNING:tensorflow:From C:\ProgramData\Anaconda3\envs\tf2c\lib\site-packages\tensorflow\python\ops\init_ops.py:1251: calling VarianceScaling.__init__ (from tensorflow.python.ops.init_ops) with dtype is deprecated and will be removed in a future version.
Instructions for updating:
Call initializer instance with the dtype argument instead of passing it to the constructor
WARNING:tensorflow:Entity <bound method GroupConv2D.call of <__main__.GroupConv2D object at 0x000001A2BBBC2748>> could not be transformed and will be executed as-is. Please report this to the AutgoGraph team. When filing the bug, set the verbosity to 10 (on Linux, `export AUTOGRAPH_VERBOSITY=10`) and attach the full output. Cause: converting <bound method GroupConv2D.call of <__main__.GroupConv2D object at 0x000001A2BBBC2748>>: 
AssertionError: Bad argument number for Name: 3, expecting 4
WARNING:tensorflow:Entity <bound method AddBias.call of <hat.model.custom.layers.basic.AddBias object at 0x000001A2BBCCB898>> could not be transformed and will be executed as-is. Please report this to the AutgoGraph team. When filing the bug, set the verbosity to 10 (on Linux, `export AUTOGRAPH_VERBOSITY=10`) and attach the full output. Cause: converting <bound method AddBias.call of <hat.model.custom.layers.basic.AddBias object at 0x000001A2BBCCB898>>: AssertionError: Bad argument number for Name: 3, expecting 4
Tensor("Group_Conv_2D/add_bias/BiasAdd:0", shape=(?, 6, 6, 16), dtype=float32)
```

### 问题解决

参考链接：[issue 32448](https://github.com/tensorflow/tensorflow/issues/32448)

```CMD
pip install -U gast==0.2.2
```

